Traceback (most recent call last):
  File "/opt/hostedtoolcache/Python/3.9.20/x64/lib/python3.9/site-packages/jupyter_cache/executors/utils.py", line 58, in single_nb_execution
    executenb(
  File "/opt/hostedtoolcache/Python/3.9.20/x64/lib/python3.9/site-packages/nbclient/client.py", line 1314, in execute
    return NotebookClient(nb=nb, resources=resources, km=km, **kwargs).execute()
  File "/opt/hostedtoolcache/Python/3.9.20/x64/lib/python3.9/site-packages/jupyter_core/utils/__init__.py", line 165, in wrapped
    return loop.run_until_complete(inner)
  File "/opt/hostedtoolcache/Python/3.9.20/x64/lib/python3.9/asyncio/base_events.py", line 647, in run_until_complete
    return future.result()
  File "/opt/hostedtoolcache/Python/3.9.20/x64/lib/python3.9/site-packages/nbclient/client.py", line 709, in async_execute
    await self.async_execute_cell(
  File "/opt/hostedtoolcache/Python/3.9.20/x64/lib/python3.9/site-packages/nbclient/client.py", line 1062, in async_execute_cell
    await self._check_raise_for_error(cell, cell_index, exec_reply)
  File "/opt/hostedtoolcache/Python/3.9.20/x64/lib/python3.9/site-packages/nbclient/client.py", line 918, in _check_raise_for_error
    raise CellExecutionError.from_cell_and_msg(cell, exec_reply_content)
nbclient.exceptions.CellExecutionError: An error occurred while executing the following cell:
------------------
# Garantir que todas as categorias de acompanhamento aparecem
categorias_acompanhamento = df_dados_gerais['freq_acompanh_fam_acolhedora'].unique()
grouped_pivot = (
    grouped_acompanhamento.pivot(index='uf', columns='freq_acompanh_fam_acolhedora', values='count')
    .reindex(columns=categorias_acompanhamento, fill_value=0)
)
------------------


[0;31m---------------------------------------------------------------------------[0m
[0;31mNameError[0m                                 Traceback (most recent call last)
Cell [0;32mIn[26], line 4[0m
[1;32m      1[0m [38;5;66;03m# Garantir que todas as categorias de acompanhamento aparecem[39;00m
[1;32m      2[0m categorias_acompanhamento [38;5;241m=[39m df_dados_gerais[[38;5;124m'[39m[38;5;124mfreq_acompanh_fam_acolhedora[39m[38;5;124m'[39m][38;5;241m.[39munique()
[1;32m      3[0m grouped_pivot [38;5;241m=[39m (
[0;32m----> 4[0m     [43mgrouped_acompanhamento[49m[38;5;241m.[39mpivot(index[38;5;241m=[39m[38;5;124m'[39m[38;5;124muf[39m[38;5;124m'[39m, columns[38;5;241m=[39m[38;5;124m'[39m[38;5;124mfreq_acompanh_fam_acolhedora[39m[38;5;124m'[39m, values[38;5;241m=[39m[38;5;124m'[39m[38;5;124mcount[39m[38;5;124m'[39m)
[1;32m      5[0m     [38;5;241m.[39mreindex(columns[38;5;241m=[39mcategorias_acompanhamento, fill_value[38;5;241m=[39m[38;5;241m0[39m)
[1;32m      6[0m )

[0;31mNameError[0m: name 'grouped_acompanhamento' is not defined

